<?xml version="1.0" encoding="utf-8"?>
<!-- =================================================================================== -->
<!-- |    This document was autogenerated by xacro from src/iiwa_stack/iiwa_description/urdf/iiwa7.urdf.xacro | -->
<!-- |    EDITING THIS FILE BY HAND IS NOT RECOMMENDED                                 | -->
<!-- =================================================================================== -->
<robot name="dual_iiwa14_ur5">
  <material name="Black">
    <color rgba="0.0 0.0 0.0 1.0"/>
  </material>
  <material name="Blue">
    <color rgba="0.0 0.0 0.8 1.0"/>
  </material>
  <material name="Green">
    <color rgba="0.0 0.8 0.0 1.0"/>
  </material>
  <material name="Grey">
    <color rgba="0.4 0.4 0.4 1.0"/>
  </material>
  <material name="Orange">
    <color rgba="1.0 0.423529411765 0.0392156862745 1.0"/>
  </material>
  <material name="Brown">
    <color rgba="0.870588235294 0.811764705882 0.764705882353 1.0"/>
  </material>
  <material name="Red">
    <color rgba="0.8 0.0 0.0 1.0"/>
  </material>
  <material name="White">
    <color rgba="1.0 1.0 1.0 1.0"/>
  </material>
  <material name="dark_grey">
    <color rgba="0.4 0.4 0.4 1"/>
  </material>
  <material name="light_grey">
    <color rgba="0.9 0.9 0.9 1"/>
  </material>
  <!-- Fix to world just for testing -->
  <link name="world"/>
  <!--joint between {parent} and link_0-->

  <!-- ROBOT 1 LEFT -->
  <!-- <joint name="world_ur5_joint_left" type="fixed">
    <origin rpy="0 -0.5 0" xyz="0 0 0"/>
    <parent link="world"/>
    <child link="ur_work_cell_link"/>
  </joint> -->
  <link name="ur_work_cell_link">
    <visual>
      <origin rpy="0 0 0" xyz="0 0 0"/>
      <material name="light_grey"/>
      <geometry>
        <mesh filename="meshes/ur5/table.stl" scale="0.001 0.001 0.001"/>
      </geometry>
    </visual>
    <collision>
      <origin rpy="0 0 0" xyz="0 0 0.4775"/>
      <geometry>
        <box size="1.28 0.82 0.945"/>
      </geometry>
    </collision>
  </link>


  <joint name="world_ur_table" type="fixed">
    <origin rpy="0 0 0" xyz="0 -0.5 0"/>
    <parent link="world"/>
    <child link="ur_work_cell_link"/>
  </joint>
  <!-- cell_base_link to parent_link -->
  <!-- <joint name="ur_work_cell_joint" type="fixed">
      <origin rpy="0 0 0" xyz="0 -0.5 0"/>
      <parent link="world" />
      <child link="ur_work_cell_link" />
  </joint> -->

  <!-- mount plate link -->
  <link name="ur_mount_plate_link">
      <visual>
          <origin rpy="0 0 0" xyz="0 0 -0.0125"/>
          <material name="dark_grey"/>
          <geometry>
              <mesh filename="meshes/ur5/mount_base_plate.stl" scale="0.000625 0.000625 0.000625"/>
          </geometry>
      </visual>
      <collision>
          <origin rpy="0 0 0" xyz="0 0 -0.0125"/>
          <geometry>
              <box size="0.25 0.25 0.025"/>
          </geometry>
      </collision>
  </link>

  <!-- mount plate base to table -->
  <joint name="ur_robot_mount_joint" type="fixed">
      <origin rpy="0 0 3.14159265359" xyz="0.47 -0.26 0.9725"/>
      <parent link="ur_work_cell_link" />
      <child link="ur_mount_plate_link" />
  </joint>

  <joint name="table_ur_joint_right" type="fixed">
    <origin rpy="0 0 1.570796325" xyz="0 0 0"/> <!--manuel offset added(Yucheng)-->
    <parent link="ur_mount_plate_link"/>
    <child link="ur5_base_link"/>
  </joint>

  <link name="ur5_base_link">
    <visual>
      <geometry>
        <mesh filename="meshes/ur5/visual/base.dae"/>
      </geometry>
      <material name="LightGrey">
        <color rgba="0.7 0.7 0.7 1.0"/>
      </material>
    </visual>
    <collision>
      <geometry>
        <mesh filename="meshes/ur5/collision/base.stl"/>
      </geometry>
    </collision>
    <inertial>
      <mass value="4.0"/>
      <origin rpy="0 0 0" xyz="0.0 0.0 0.0"/>
      <inertia ixx="0.00443333156" ixy="0.0" ixz="0.0" iyy="0.00443333156" iyz="0.0" izz="0.0072"/>
    </inertial>
  </link>
  <joint name="shoulder_pan_joint" type="revolute">
    <parent link="ur5_base_link"/>
    <child link="shoulder_link"/>
    <origin rpy="0.0 0.0 0.0" xyz="0.0 0.0 0.089159"/>
    <axis xyz="0 0 1"/>
    <limit effort="150.0" lower="-3.14159265359" upper="3.14159265359" velocity="3.15"/>
    <!-- Joint lower/upper bound anually limited -->
    <dynamics damping="0.0" friction="0.0"/>
  </joint>
  <link name="shoulder_link">
    <visual>
      <geometry>
        <mesh filename="meshes/ur5/visual/shoulder.dae"/>
      </geometry>
      <material name="LightGrey">
        <color rgba="0.7 0.7 0.7 1.0"/>
      </material>
    </visual>
    <collision>
      <geometry>
        <mesh filename="meshes/ur5/collision/shoulder.stl"/>
      </geometry>
    </collision>
    <inertial>
      <mass value="3.7"/>
      <origin rpy="0 0 0" xyz="0.0 0.0 0.0"/>
      <inertia ixx="0.010267495893" ixy="0.0" ixz="0.0" iyy="0.010267495893" iyz="0.0" izz="0.00666"/>
    </inertial>
  </link>
  <joint name="shoulder_lift_joint" type="revolute">
    <parent link="shoulder_link"/>
    <child link="upper_arm_link"/>
    <origin rpy="0.0 0.0 0.0" xyz="0.0 0.13585 0.0"/>
    <axis xyz="0 1 0"/>
    <limit effort="150.0" lower="-3.14159265359" upper="3.14159265359" velocity="3.15"/>
    <dynamics damping="0.0" friction="0.0"/>
  </joint>
  <link name="upper_arm_link">
    <visual>
      <geometry>
        <mesh filename="meshes/ur5/visual/upperarm.dae"/>
      </geometry>
      <material name="LightGrey">
        <color rgba="0.7 0.7 0.7 1.0"/>
      </material>
    </visual>
    <collision>
      <geometry>
        <mesh filename="meshes/ur5/collision/upperarm.stl"/>
      </geometry>
    </collision>
    <inertial>
      <mass value="8.393"/>
      <origin rpy="0 0 0" xyz="0.0 0.0 0.28"/>
      <inertia ixx="0.22689067591" ixy="0.0" ixz="0.0" iyy="0.22689067591" iyz="0.0" izz="0.0151074"/>
    </inertial>
  </link>
  <joint name="elbow_joint" type="revolute">
    <parent link="upper_arm_link"/>
    <child link="forearm_link"/>
    <origin rpy="0.0 0.0 0.0" xyz="0.0 -0.1197 0.425"/>
    <axis xyz="0 1 0"/>
    <limit effort="150.0" lower="-3.14159265359" upper="3.14159265359" velocity="3.15"/>
    <dynamics damping="0.0" friction="0.0"/>
  </joint>
  <link name="forearm_link">
    <visual>
      <geometry>
        <mesh filename="meshes/ur5/visual/forearm.dae"/>
      </geometry>
      <material name="LightGrey">
        <color rgba="0.7 0.7 0.7 1.0"/>
      </material>
    </visual>
    <collision>
      <geometry>
        <mesh filename="meshes/ur5/collision/forearm.stl"/>
      </geometry>
    </collision>
    <inertial>
      <mass value="2.275"/>
      <origin rpy="0 0 0" xyz="0.0 0.0 0.25"/>
      <inertia ixx="0.049443313556" ixy="0.0" ixz="0.0" iyy="0.049443313556" iyz="0.0" izz="0.004095"/>
    </inertial>
  </link>
  <joint name="wrist_1_joint" type="revolute">
    <parent link="forearm_link"/>
    <child link="wrist_1_link"/>
    <origin rpy="0.0 0.0 0.0" xyz="0.0 0.0 0.39225"/>
    <axis xyz="0 1 0"/>
    <limit effort="28.0" lower="-3.14159265359" upper="3.14159265359" velocity="3.2"/>
    <dynamics damping="0.0" friction="0.0"/>
  </joint>
  <link name="wrist_1_link">
    <visual>
      <geometry>
        <mesh filename="meshes/ur5/visual/wrist1.dae"/>
      </geometry>
      <material name="LightGrey">
        <color rgba="0.7 0.7 0.7 1.0"/>
      </material>
    </visual>
    <collision>
      <geometry>
        <mesh filename="meshes/ur5/collision/wrist1.stl"/>
      </geometry>
    </collision>
    <inertial>
      <mass value="1.219"/>
      <origin rpy="0 0 0" xyz="0.0 0.0 0.0"/>
      <inertia ixx="0.111172755531" ixy="0.0" ixz="0.0" iyy="0.111172755531" iyz="0.0" izz="0.21942"/>
    </inertial>
  </link>
  <joint name="wrist_2_joint" type="revolute">
    <parent link="wrist_1_link"/>
    <child link="wrist_2_link"/>
    <origin rpy="0.0 0.0 0.0" xyz="0.0 0.093 0.0"/>
    <axis xyz="0 0 1"/>
    <limit effort="28.0" lower="-3.14159265359" upper="3.14159265359" velocity="3.2"/>
    <dynamics damping="0.0" friction="0.0"/>
  </joint>
  <link name="wrist_2_link">
    <visual>
      <geometry>
        <mesh filename="meshes/ur5/visual/wrist2.dae"/>
      </geometry>
      <material name="LightGrey">
        <color rgba="0.7 0.7 0.7 1.0"/>
      </material>
    </visual>
    <collision>
      <geometry>
        <mesh filename="meshes/ur5/collision/wrist2.stl"/>
      </geometry>
    </collision>
    <inertial>
      <mass value="1.219"/>
      <origin rpy="0 0 0" xyz="0.0 0.0 0.0"/>
      <inertia ixx="0.111172755531" ixy="0.0" ixz="0.0" iyy="0.111172755531" iyz="0.0" izz="0.21942"/>
    </inertial>
  </link>
  <joint name="wrist_3_joint" type="revolute">
    <parent link="wrist_2_link"/>
    <child link="wrist_3_link"/>
    <origin rpy="0.0 0.0 0.0" xyz="0.0 0.0 0.09465"/>
    <axis xyz="0 1 0"/>
    <limit effort="28.0" lower="-3.14159265359" upper="3.14159265359" velocity="3.2"/>
    <dynamics damping="0.0" friction="0.0"/>
  </joint>
  <link name="wrist_3_link">
    <visual>
      <geometry>
        <mesh filename="meshes/ur5/visual/wrist3.dae"/>
      </geometry>
      <material name="LightGrey">
        <color rgba="0.7 0.7 0.7 1.0"/>
      </material>
    </visual>
    <collision>
      <geometry>
        <mesh filename="meshes/ur5/collision/wrist3.stl"/>
      </geometry>
    </collision>
    <inertial>
      <mass value="0.1879"/>
      <origin rpy="0 0 0" xyz="0.0 0.0 0.0"/>
      <inertia ixx="0.0171364731454" ixy="0.0" ixz="0.0" iyy="0.0171364731454" iyz="0.0" izz="0.033822"/>
    </inertial>
  </link>
  <joint name="ee_fixed_joint" type="fixed">
    <parent link="wrist_3_link"/>
    <child link="ee_link"/>
    <origin rpy="0.0 0.0 1.570796325" xyz="0.0 0.0823 0.0"/>
  </joint>
  <link name="ee_link">
    <collision>
      <geometry>
        <box size="0.01 0.01 0.01"/>
      </geometry>
      <origin rpy="0 0 0" xyz="-0.01 0 0"/>
    </collision>
  </link>
  <transmission name="shoulder_pan_trans">
    <type>transmission_interface/SimpleTransmission</type>
    <joint name="shoulder_pan_joint">
      <hardwareInterface>PositionJointInterface</hardwareInterface>
    </joint>
    <actuator name="shoulder_pan_motor">
      <mechanicalReduction>1</mechanicalReduction>
    </actuator>
  </transmission>
  <transmission name="shoulder_lift_trans">
    <type>transmission_interface/SimpleTransmission</type>
    <joint name="shoulder_lift_joint">
      <hardwareInterface>PositionJointInterface</hardwareInterface>
    </joint>
    <actuator name="shoulder_lift_motor">
      <mechanicalReduction>1</mechanicalReduction>
    </actuator>
  </transmission>
  <transmission name="elbow_trans">
    <type>transmission_interface/SimpleTransmission</type>
    <joint name="elbow_joint">
      <hardwareInterface>PositionJointInterface</hardwareInterface>
    </joint>
    <actuator name="elbow_motor">
      <mechanicalReduction>1</mechanicalReduction>
    </actuator>
  </transmission>
  <transmission name="wrist_1_trans">
    <type>transmission_interface/SimpleTransmission</type>
    <joint name="wrist_1_joint">
      <hardwareInterface>PositionJointInterface</hardwareInterface>
    </joint>
    <actuator name="wrist_1_motor">
      <mechanicalReduction>1</mechanicalReduction>
    </actuator>
  </transmission>
  <transmission name="wrist_2_trans">
    <type>transmission_interface/SimpleTransmission</type>
    <joint name="wrist_2_joint">
      <hardwareInterface>PositionJointInterface</hardwareInterface>
    </joint>
    <actuator name="wrist_2_motor">
      <mechanicalReduction>1</mechanicalReduction>
    </actuator>
  </transmission>
  <transmission name="wrist_3_trans">
    <type>transmission_interface/SimpleTransmission</type>
    <joint name="wrist_3_joint">
      <hardwareInterface>PositionJointInterface</hardwareInterface>
    </joint>
    <actuator name="wrist_3_motor">
      <mechanicalReduction>1</mechanicalReduction>
    </actuator>
  </transmission>
  <!-- nothing to do here at the moment -->
  <!-- ROS base_link to UR 'Base' Coordinates transform -->
  <link name="base"/>
  <joint name="base_link-base_fixed_joint" type="fixed">
    <!-- NOTE: this rotation is only needed as long as base_link itself is
                 not corrected wrt the real robot (ie: rotated over 180
                 degrees)
      -->
    <origin rpy="0 0 -3.14159265" xyz="0 0 0"/>
    <parent link="ur5_base_link"/>
    <child link="base"/>
  </joint>
  <!-- Frame coincident with all-zeros TCP on UR controller -->
  <link name="tool0"/>
  <joint name="wrist_3_link-tool0_fixed_joint" type="fixed">
    <origin rpy="-1.570796325 0 0" xyz="0 0.0823 0"/>
    <parent link="wrist_3_link"/>
    <child link="tool0"/>
  </joint>

  <link name="zimmer_match_robot_part_ur">
      <visual>
        <origin xyz="0 0 -0.028" rpy="-1.5707963268 0 0" />
        <material name="black" />
        <geometry>
          <mesh filename="meshes/iiwa14/zimmer_match_robot_part.stl" scale="0.001 0.001 0.001"/>
        </geometry>
      </visual>
      <collision>
        <origin xyz="0 0 -0.014" rpy="0 0 0" />
        <geometry>
          <cylinder length="0.028" radius="0.04"/>
        </geometry>
      </collision>
    </link>

    <joint name="zimmer_match_robo_part_to_ee_ur" type="fixed">
      <origin xyz="0 0 0" rpy="0 0 1.5707963268" />
      <parent link="tool0" />
      <child link="zimmer_match_robot_part_ur" />
    </joint>

    <joint name="zimmer_gripper_to_zimmer_match_robo_part_ur" type="fixed">
      <origin xyz="0 0 0" rpy="0 0 1.5707963268" />
      <parent link="zimmer_match_robot_part_ur" />
      <child link="zimmer_gripper_ur" />
    </joint>

    <link name="zimmer_gripper_ur">
      <visual>
        <origin xyz="0 0 0" rpy="-1.5707963268 0 0" />
        <material name="white">
            <color rgba="1 1 1 1"/>
        </material>
        <geometry>
          <mesh filename="meshes/iiwa14/zimmer_match_gripper.stl" scale="0.001 0.001 0.001"/>
        </geometry>
      </visual>
      <collision>
        <origin xyz="0 0 0" rpy="-1.5707963268 0 0" />
        <geometry>
          <mesh filename="meshes/iiwa14/zimmer_match_gripper.stl" scale="0.001 0.001 0.001"/>
        </geometry>
      </collision>
    </link>

    <joint name="zimmer_left_jaw_to_zimmer_gripper_ur" type="fixed">
      <origin xyz="0 0 0" rpy="0 0 1.5707963268" />
      <parent link="zimmer_gripper_ur" />
      <child link="zimmer_left_jaw_ur" />
    </joint>

    <link name="zimmer_left_jaw_ur">
      <visual>
        <origin xyz="0 -0.03 0.08" rpy="-1.5707963268 0 1.5707963268" />
        <material name="white">
            <color rgba="1 1 1 1"/>
        </material>
        <geometry>
          <mesh filename="meshes/iiwa14/zimmer_left_jaw.stl" scale="0.001 0.001 0.001"/>
        </geometry>
      </visual>
      <collision>
        <origin xyz="0 -0.03 0.08" rpy="-1.5707963268 0 1.5707963268" />
        <geometry>
          <mesh filename="meshes/iiwa14/zimmer_left_jaw.stl" scale="0.001 0.001 0.001"/>
        </geometry>
      </collision>
    </link>

     <joint name="zimmer_right_jaw_to_zimmer_gripper_ur" type="fixed">
      <origin xyz="0 0 0" rpy="0 0 1.5707963268" />
      <parent link="zimmer_gripper_ur" />
      <child link="zimmer_right_jaw_ur" />
    </joint>

    <link name="zimmer_right_jaw_ur">
      <visual>
        <origin xyz="0 0.01 0.08" rpy="-1.5707963268 0 -1.5707963268" />
        <material name="white">
            <color rgba="1 1 1 1"/>
        </material>
        <geometry>
          <mesh filename="meshes/iiwa14/zimmer_right_jaw.stl" scale="0.001 0.001 0.001"/>
        </geometry>
      </visual>
      <collision>
        <origin xyz="0 0.01 0.08" rpy="-1.5707963268 0 -1.5707963268" />
        <geometry>
          <mesh filename="meshes/iiwa14/zimmer_right_jaw.stl" scale="0.001 0.001 0.001"/>
        </geometry>
      </collision>
    </link>

    <link name="zimmer_ee_ur"/>

    <joint name="zimmer_ee_to_zimmer_gripper_ur" type="fixed">
      <origin xyz="0 0 0.2" rpy="0 0 -3.14159265359" />
      <parent link="zimmer_gripper_ur" />
      <child link="zimmer_ee_ur" />
    </joint>

    <!-- Attached Object  -->
    <link name="attached_object">
    <visual>
      <origin xyz="0 0 0" rpy="0 0 0" />
      <geometry>
        <sphere radius="0.15"/>
      </geometry>
      <material name="Cyan">
          <color rgba="0 1.0 1.0 1.0"/>
      </material>
    </visual>
    <collision>
      <origin xyz="0 0 0" rpy="0 0 0" />
      <geometry>
        <sphere radius="0.1"/>
      </geometry>
    </collision>
  </link>
  <joint name="object_tool0_fixed_joint" type="fixed">
    <origin rpy="0 0 0" xyz="0 0 0"/>
    <parent link="zimmer_ee_ur"/>
    <child link="attached_object"/>
  </joint>


  <!-- ROBOT 2 RIGHT -->
  <joint name="world_iiwa_table" type="fixed">
    <origin rpy="0 0 0" xyz="0 0.5 0"/>
    <parent link="world"/>
    <child link="work_cell_link_right"/>
  </joint>

  <link name="work_cell_link_right">
    <visual>
      <origin rpy="0 0 0" xyz="0 0 0"/>
      <material name="light_grey"/>
      <geometry>
        <mesh filename="meshes/iiwa14/table.stl" scale="0.001 0.001 0.001"/>
      </geometry>
    </visual>
    <collision>
      <origin rpy="0 0 0" xyz="0 0 0.4775"/>
      <geometry>
        <box size="1.28 0.82 0.945"/>
      </geometry>
    </collision>
  </link>

  <joint name="iiwa_mount_joint" type="fixed">
    <origin rpy="0 0 3.14159265359" xyz="0.43 0.2 0.9725"/>
    <parent link="work_cell_link_right" />
    <child link="mount_plate_link" />
  </joint>

  <link name="mount_plate_link">
    <visual>
      <origin rpy="0 0 0" xyz="0 0 -0.0125"/>
      <material name="dark_grey"/>
      <geometry>
        <mesh filename="meshes/iiwa14/mount_base_plate.stl" scale="0.001 0.001 0.001"/>
      </geometry>
    </visual>
    <collision>
      <origin rpy="0 0 0" xyz="0 0 -0.0125"/>
      <geometry>
        <box size="0.42 0.42 0.025"/>
      </geometry>
    </collision>
  </link>

  <joint name="table_iiwa_joint_right" type="fixed">
    <origin rpy="0 0 0" xyz="0 0 0"/>
    <parent link="mount_plate_link"/>
    <child link="iiwa_link_0_right"/>
  </joint>
  <link name="iiwa_link_0_right">
      <inertial>
        <origin xyz="-0.1 0 0.07" rpy="0 0 0"/>
        <mass value="5"/>
        <inertia ixx="0.05"  ixy="0"  ixz="0" iyy="0.06" iyz="0" izz="0.03" />
      </inertial>

      <visual>
        <origin xyz="0 0 0" rpy="0 0 0"/>
        <geometry>
          <mesh filename="meshes/iiwa14/visual/link_0.stl"/>
        </geometry>
        <material name="Grey"/>
      </visual>

      <collision>
        <origin xyz="0 0 0" rpy="0 0 0"/>
        <geometry>
          <mesh filename="meshes/iiwa14/collision/link_0.stl"/>
        </geometry>
        <material name="Grey"/>
      </collision>

      <self_collision_checking>
        <origin xyz="0 0 0" rpy="0 0 0"/>
        <geometry>
          <capsule radius="0.15" length="0.25"/>
        </geometry>
      </self_collision_checking>

    </link>

    <!-- joint between link_0 and link_1 -->
    <joint name="iiwa_joint_1_right" type="revolute">
      <parent link="iiwa_link_0_right"/>
      <child link="iiwa_link_1_right"/>
      <origin xyz="0 0 0.1575" rpy="0 0 0"/>
      <axis xyz="0 0 1"/>
      <limit lower="-2.96705972839" upper="2.96705972839"
             effort="300" velocity="10" />
      <safety_controller soft_lower_limit="-2.93215314335"
                         soft_upper_limit="2.93215314335"
                         k_position="100"
                         k_velocity="2"/>
      <dynamics damping="0.5"/>
    </joint>

    <link name="iiwa_link_1_right">
      <inertial>
        <origin xyz="0 -0.03 0.12" rpy="0 0 0"/>
        <mass value="4"/>
        <inertia ixx="0.1"  ixy="0"  ixz="0" iyy="0.09" iyz="0" izz="0.02" />
      </inertial>

      <visual>
        <origin xyz="0 0 0" rpy="0 0 0"/>
        <geometry>
          <mesh filename="meshes/iiwa14/visual/link_1.stl"/>
        </geometry>
        <material name="Orange"/>
      </visual>

      <collision>
        <origin xyz="0 0 0" rpy="0 0 0"/>
        <geometry>
          <mesh filename="meshes/iiwa14/collision/link_1.stl"/>
        </geometry>
        <material name="Orange"/>
      </collision>
    </link>

    <!-- joint between link_1 and link_2 -->
    <joint name="iiwa_joint_2_right" type="revolute">
      <parent link="iiwa_link_1_right"/>
      <child link="iiwa_link_2_right"/>
      <origin xyz="0 0 0.2025" rpy="1.57079632679   0 3.14159265359"/>
      <axis xyz="0 0 1"/>
      <limit lower="-2.09439510239" upper="2.09439510239"
             effort="300" velocity="10" />
      <safety_controller soft_lower_limit="-2.05948851735"
                         soft_upper_limit="2.05948851735"
                         k_position="100"
                         k_velocity="2"/>
      <dynamics damping="0.5"/>
    </joint>

    <link name="iiwa_link_2_right">
      <inertial>
        <origin xyz="0.0003 0.059 0.042" rpy="0 0 0"/>
        <mass value="4"/>
        <inertia ixx="0.05"  ixy="0"  ixz="0" iyy="0.018" iyz="0" izz="0.044" />
      </inertial>

      <visual>
        <origin xyz="0 0 0" rpy="0 0 0"/>
        <geometry>
          <mesh filename="meshes/iiwa14/visual/link_2.stl"/>
        </geometry>
        <material name="Orange"/>
      </visual>

      <collision>
        <origin xyz="0 0 0" rpy="0 0 0"/>
        <geometry>
          <mesh filename="meshes/iiwa14/collision/link_2.stl"/>
        </geometry>
        <material name="Orange"/>
      </collision>
    </link>

    <!-- joint between link_2 and link_3 -->
    <joint name="iiwa_joint_3_right" type="revolute">
      <parent link="iiwa_link_2_right"/>
      <child link="iiwa_link_3_right"/>
      <origin xyz="0 0.2045 0" rpy="1.57079632679 0 3.14159265359"/>
      <axis xyz="0 0 1"/>
      <limit lower="-2.96705972839" upper="2.96705972839"
             effort="300" velocity="10" />
      <safety_controller soft_lower_limit="-2.93215314335"
                         soft_upper_limit="2.93215314335"
                         k_position="100"
                         k_velocity="2"/>
      <dynamics damping="0.5"/>
    </joint>

    <link name="iiwa_link_3_right">
      <inertial>
        <origin xyz="0 0.03 0.13" rpy="0 0 0"/>
        <mass value="3"/>
        <inertia ixx="0.08"  ixy="0"  ixz="0" iyy="0.075" iyz="0" izz="0.01" />
      </inertial>

      <visual>
        <origin xyz="0 0 0" rpy="0 0 0"/>
        <geometry>
          <mesh filename="meshes/iiwa14/visual/link_3.stl"/>
        </geometry>
        <material name="Orange"/>
      </visual>

      <collision>
        <origin xyz="0 0 0" rpy="0 0 0"/>
        <geometry>
          <mesh filename="meshes/iiwa14/collision/link_3.stl"/>
        </geometry>
        <material name="Orange"/>
      </collision>
    </link>

    <!-- joint between link_3 and link_4 -->
    <joint name="iiwa_joint_4_right" type="revolute">
      <parent link="iiwa_link_3_right"/>
      <child link="iiwa_link_4_right"/>
      <origin xyz="0 0 0.2155" rpy="1.57079632679 0 0"/>
      <axis xyz="0 0 1"/>
      <limit lower="-2.09439510239" upper="2.09439510239"
             effort="300" velocity="10" />
      <safety_controller soft_lower_limit="-2.05948851735"
                         soft_upper_limit="2.05948851735"
                         k_position="100"
                         k_velocity="2"/>
      <dynamics damping="0.5"/>
    </joint>

    <link name="iiwa_link_4_right">
      <inertial>
        <origin xyz="0 0.067 0.034" rpy="0 0 0"/>
        <mass value="2.7"/>
        <inertia ixx="0.03"  ixy="0"  ixz="0" iyy="0.01" iyz="0" izz="0.029" />
      </inertial>

      <visual>
        <origin xyz="0 0 0" rpy="0 0 0"/>
        <geometry>
          <mesh filename="meshes/iiwa14/visual/link_4.stl"/>
        </geometry>
        <material name="Orange"/>
      </visual>

      <collision>
        <origin xyz="0 0 0" rpy="0 0 0"/>
        <geometry>
          <mesh filename="meshes/iiwa14/collision/link_4.stl"/>
        </geometry>
        <material name="Orange"/>
      </collision>
    </link>

    <!-- joint between link_4 and link_5 -->
    <joint name="iiwa_joint_5_right" type="revolute">
      <parent link="iiwa_link_4_right"/>
      <child link="iiwa_link_5_right"/>
      <origin xyz="0 0.1845 0" rpy="-1.57079632679 3.14159265359 0"/>
      <axis xyz="0 0 1"/>
      <limit lower="-2.96705972839" upper="2.96705972839"
             effort="300" velocity="10" />
      <safety_controller soft_lower_limit="-2.93215314335"
                         soft_upper_limit="2.93215314335"
                         k_position="100"
                         k_velocity="2"/>
      <dynamics damping="0.5"/>
    </joint>

    <link name="iiwa_link_5_right">
      <inertial>
        <origin xyz="0.0001 0.021 0.076" rpy="0 0 0"/>
        <mass value="1.7"/>
        <inertia ixx="0.02"  ixy="0"  ixz="0" iyy="0.018" iyz="0" izz="0.005" />
      </inertial>

      <visual>
        <origin xyz="0 0 0" rpy="0 0 0"/>
        <geometry>
          <mesh filename="meshes/iiwa14/visual/link_5.stl"/>
        </geometry>
        <material name="Orange"/>
      </visual>

      <collision>
        <origin xyz="0 0 0" rpy="0 0 0"/>
        <geometry>
          <mesh filename="meshes/iiwa14/collision/link_5.stl"/>
        </geometry>
        <material name="Orange"/>
      </collision>
    </link>

    <!-- joint between link_5 and link_6 -->
    <joint name="iiwa_joint_6_right" type="revolute">
      <parent link="iiwa_link_5_right"/>
      <child link="iiwa_link_6_right"/>
      <origin xyz="0 0 0.2155" rpy="1.57079632679 0 0"/>
      <axis xyz="0 0 1"/>
      <limit lower="-2.09439510239" upper="2.09439510239"
             effort="300" velocity="10" />
      <safety_controller soft_lower_limit="-2.05948851735"
                         soft_upper_limit="2.05948851735"
                         k_position="100"
                         k_velocity="2"/>
      <dynamics damping="0.5"/>
    </joint>

    <link name="iiwa_link_6_right">
      <inertial>
        <origin xyz="0 0.0006 0.0004" rpy="0 0 0"/>
        <mass value="1.8"/>
        <inertia ixx="0.005"  ixy="0"  ixz="0" iyy="0.0036" iyz="0" izz="0.0047" />
      </inertial>

      <visual>
        <origin xyz="0 0 0" rpy="0 0 0"/>
        <geometry>
          <mesh filename="meshes/iiwa14/visual/link_6.stl"/>
        </geometry>
        <material name="Orange"/>
      </visual>

      <collision>
        <origin xyz="0 0 0" rpy="0 0 0"/>
        <geometry>
          <mesh filename="meshes/iiwa14/collision/link_6.stl"/>
        </geometry>
        <material name="Orange"/>
      </collision>
    </link>

    <!-- joint between link_6 and link_7 -->
    <joint name="iiwa_joint_7_right" type="revolute">
      <parent link="iiwa_link_6_right"/>
      <child link="iiwa_link_7_right"/>
      <origin xyz="0 0.081 0" rpy="-1.57079632679 3.14159265359 0"/>
      <axis xyz="0 0 1"/>
      <limit lower="-3.05432619099" upper="3.05432619099"
             effort="300" velocity="10" />
      <safety_controller soft_lower_limit="-3.01941960595"
                         soft_upper_limit="3.01941960595"
                         k_position="100"
                         k_velocity="2"/>
      <dynamics damping="0.5"/>
    </joint>

    <link name="iiwa_link_7_right">
      <inertial>
        <origin xyz="0 0 0.02" rpy="0 0 0"/>
        <mass value="0.3"/>
        <inertia ixx="0.001"  ixy="0"  ixz="0" iyy="0.001" iyz="0" izz="0.001" />
      </inertial>

      <visual>
        <origin xyz="0 0 0" rpy="0 0 0"/>
        <geometry>
          <mesh filename="meshes/iiwa14/visual/link_7.stl"/>
        </geometry>
        <material name="Grey"/>
      </visual>

      <collision>
        <origin xyz="0 0 0" rpy="0 0 0"/>
        <geometry>
          <mesh filename="meshes/iiwa14/collision/link_7.stl"/>
        </geometry>
        <material name="Grey"/>
      </collision>
    </link>

    <joint name="iiwa_joint_ee_right" type="fixed">
      <parent link="iiwa_link_7_right"/>
      <child link="iiwa_link_ee_right"/>
      <origin xyz="0 0 0.045" rpy="0 0 0"/>
    </joint>

    <link name="iiwa_link_ee_right">
    </link>

    <link name="zimmer_match_robo_part_iiwa">
      <visual>
        <origin xyz="0 0 -0.028" rpy="-1.5707963268 0 0" />
        <material name="black" />
        <geometry>
          <mesh filename="meshes/iiwa14/zimmer_match_robot_part.stl" scale="0.001 0.001 0.001"/>
        </geometry>
      </visual>
      <collision>
        <origin xyz="0 0 -0.014" rpy="0 0 0" />
        <geometry>
          <cylinder length="0.028" radius="0.04"/>
        </geometry>
      </collision>
    </link>

    <joint name="zimmer_match_robo_part_to_ee_iiwa" type="fixed">
      <origin xyz="0 0 0.03" rpy="0 0 1.5707963268" />
      <parent link="iiwa_link_ee_right" />
      <child link="zimmer_match_robo_part_iiwa" />
    </joint>

    <joint name="zimmer_gripper_to_zimmer_match_robo_part_iiwa" type="fixed">
      <origin xyz="0 0 0" rpy="0 0 1.5707963268" />
      <parent link="zimmer_match_robo_part_iiwa" />
      <child link="zimmer_gripper_iiwa" />
    </joint>

    <link name="zimmer_gripper_iiwa">
      <visual>
        <origin xyz="0 0 0" rpy="-1.5707963268 0 0" />
        <material name="white">
            <color rgba="1 1 1 1"/>
        </material>
        <geometry>
          <mesh filename="meshes/iiwa14/zimmer_match_gripper.stl" scale="0.001 0.001 0.001"/>
        </geometry>
      </visual>
      <collision>
        <origin xyz="0 0 0" rpy="-1.5707963268 0 0" />
        <geometry>
          <mesh filename="meshes/iiwa14/zimmer_match_gripper.stl" scale="0.001 0.001 0.001"/>
        </geometry>
      </collision>
    </link>

    <joint name="zimmer_left_jaw_to_zimmer_gripper_iiwa" type="fixed">
      <origin xyz="0 0 0" rpy="0 0 1.5707963268" />
      <parent link="zimmer_gripper_iiwa" />
      <child link="zimmer_left_jaw_iiwa" />
    </joint>

    <link name="zimmer_left_jaw_iiwa">
      <visual>
        <origin xyz="0 -0.03 0.08" rpy="-1.5707963268 0 1.5707963268" />
        <material name="white">
            <color rgba="1 1 1 1"/>
        </material>
        <geometry>
          <mesh filename="meshes/iiwa14/zimmer_left_jaw.stl" scale="0.001 0.001 0.001"/>
        </geometry>
      </visual>
      <collision>
        <origin xyz="0 -0.03 0.08" rpy="-1.5707963268 0 1.5707963268" />
        <geometry>
          <mesh filename="meshes/iiwa14/zimmer_left_jaw.stl" scale="0.001 0.001 0.001"/>
        </geometry>
      </collision>
    </link>

     <joint name="zimmer_right_jaw_to_zimmer_gripper_iiwa" type="fixed">
      <origin xyz="0 0 0" rpy="0 0 1.5707963268" />
      <parent link="zimmer_gripper_iiwa" />
      <child link="zimmer_right_jaw_iiwa" />
    </joint>

    <link name="zimmer_right_jaw_iiwa">
      <visual>
        <origin xyz="0 0.01 0.08" rpy="-1.5707963268 0 -1.5707963268" />
        <material name="white">
            <color rgba="1 1 1 1"/>
        </material>
        <geometry>
          <mesh filename="meshes/iiwa14/zimmer_right_jaw.stl" scale="0.001 0.001 0.001"/>
        </geometry>
      </visual>
      <collision>
        <origin xyz="0 0.01 0.08" rpy="-1.5707963268 0 -1.5707963268" />
        <geometry>
          <mesh filename="meshes/iiwa14/zimmer_right_jaw.stl" scale="0.001 0.001 0.001"/>
        </geometry>
      </collision>
    </link>

    <link name="zimmer_ee_iiwa"/>

    <joint name="zimmer_ee_to_zimmer_gripper_iiwa" type="fixed">
      <origin xyz="0 0 0.2" rpy="0 0 -3.14159265359" />
      <parent link="zimmer_gripper_iiwa" />
      <child link="zimmer_ee_iiwa" />
    </joint>

    <!--<link name="schmalz_gripper_link">
        <visual>
            <origin rpy="-1.5707963268 0 0" xyz="0 0 0"/>
            <geometry>
                <mesh filename="meshes/iiwa14/schmalz_gripper.stl" scale="0.001 0.001 0.001"/>
            </geometry>
            <material name="white">
                <color rgba="1 1 1 1"/>
            </material>
        </visual>
        <collision>
            <origin rpy="0 0 0" xyz="0 0 0"/>
            <geometry>
                <mesh filename="meshes/iiwa14/schmalz_gripper.stl" scale="0.001 0.001 0.001"/>
            </geometry>
        </collision>
        <inertial>
            <mass value="1"/>
            <origin rpy="0 0 0" xyz="0 0 0"/>
            <inertia ixx="1" ixy="0" ixz="0" iyy="1" iyz="0" izz="1"/>
        </inertial>
    </link>
    <joint name="schmalz_gripper_joint" type="fixed">
        <origin rpy="0 0 0" xyz="0 0 0"/>
        <parent link="zimmer_match_robo_part" />
        <child link="schmalz_gripper_link" />
    </joint>




    <link name="object">
    <visual>
      <origin xyz="0 0 0" rpy="0 0 0" />
      <geometry>
        <sphere radius="0.001"/>
      </geometry>
      <material name="Cyan">
          <color rgba="0 1.0 1.0 1.0"/>
      </material>
    </visual>
    <collision>
      <origin xyz="0 0 0" rpy="0 0 0" />
      <geometry>
        <sphere radius="0.1"/>
      </geometry>
    </collision>
  </link>
  <joint name="object_tool0_fixed_joint" type="fixed">
    <origin rpy="0 0 0" xyz="0 0 0.2"/>
    <parent link="schmalz_gripper_link"/>
    <child link="object"/>
  </joint> -->


</robot>

